<?xml version="1.0"?>
<robot xmlns:xacro="http://ros.org/wiki/xacro">

<xacro:property name="mmTom" value="0.001" />
<xacro:property name="mm2Tom2" value="${0.001*0.001}" />

<xacro:property name="PI" value="3.14159265359" />
<xacro:property name="PI_2" value="1.57079632679" />

<xacro:property name="toRad" value="${PI/180.0}" />

<!-- LINKS -->
<!-- This links are defined in order to be compliant with http://www.ros.org/reps/rep-0120.html#coordinate-frames
and to define the end effectors of the robot-->


<!-- The coordinate frame called torso is attached to the lowest body of the model which is a parent of l_gripper, r_gripper and gaze. -->

  <link name ="DWL">
    <inertial>
      <origin xyz="${-1.3438629e+01*mmTom} ${-2.4995993e-02*mmTom} ${7.3562799e+01*mmTom}" rpy="0 0 0"/>
      <mass value="2.4309068"/>
      <inertia ixx="${1.6702798e+04*mm2Tom2}"  ixy="${3.5908153e+01*mm2Tom2}"  ixz="${-4.1709274e+03*mm2Tom2}" iyy="${1.9440925e+04*mm2Tom2}" iyz="${1.1578036e+01*mm2Tom2}" izz="${5.7721068e+03*mm2Tom2}" />
    </inertial>
    <visual>
      <origin xyz="0.0 0.0 0.0" rpy="0 0 0"/>
      <geometry name="DWL_visual">
        <mesh filename="package://walkman_urdf/meshes/TorsoRoll.STL" scale="0.001 0.001 0.001" />
      </geometry>
      <material name="dark_grey"/>
    </visual>
    <collision>
      <origin xyz="0.0 0.0 0.0" rpy="0 0 0"/>
      <geometry name="DWL_collision">
        <mesh filename="package://walkman_urdf/meshes/simple/TorsoRoll.STL" scale="0.001 0.001 0.001" />
      </geometry>             
    </collision>
  </link>


  <link name ="DWYTorso">
    <inertial>
        <origin xyz="${-5.7472215e+01*mmTom} ${2.8579335e-01*mmTom} ${4.7027898e+01*mmTom}" rpy="0 0 0"/>
        <mass value="1.3589958e+01"/>
      <inertia ixx="${8.0724191e+09*mm2Tom2}"  ixy="${1.0430870e+07*mm2Tom2}"  ixz="${-2.7899108e+06*mm2Tom2}" iyy="${6.0674683e+09*mm2Tom2}" iyz="${-3.6025234e+06*mm2Tom2}" izz="${8.9204199e+09*mm2Tom2}" />
    </inertial>
    <visual>
      <origin xyz="0.0 0.0 0.0" rpy="0 0 0"/>
      <geometry name="DWYTorso_visual">
        <mesh filename="package://walkman_urdf/meshes/Chest.STL" scale="0.001 0.001 0.001" />
      </geometry>
      <material name="blue"/>
    </visual>
    <collision>
      <origin xyz="0.0 0.0 0.0" rpy="0 0 0"/>
      <geometry name="DWYTorso_collision">
        <mesh filename="package://walkman_urdf/meshes/simple/Chest.STL" scale="0.001 0.001 0.001" />
      </geometry>             
    </collision>
  </link>

 <!--link name="torso"/-->

<!-- JOINTS -->
<!--joint name="torso_joint" type="fixed">
    <parent link="DWYTorso"/>
    <child link="torso"/>
    <origin xyz="0.0 0 0.0" rpy="0 0 0" /> 
</joint-->

<joint name="WaistLat" type="revolute"> 
    <parent link="Waist"/>
    <child link="DWL"/>
    <origin xyz="${59.6*mmTom} 0 0.0" rpy="0 0 0" />
    <axis xyz="1 0 0" />
    <limit velocity="6.283" effort="120" lower="${-35.0*toRad}" upper="${35.0*toRad}" />
    <dynamics friction="0" damping="3.0"/> 
</joint>


<joint name="WaistYaw" type="revolute">
    <parent link="DWL"/>
    <child link="DWYTorso"/>
    <origin xyz="${8.8*mmTom} 0 ${222.15*mmTom}" rpy="0 0 0" />
    <axis xyz="0 0 1" />
    <limit velocity="6.283" effort="120" lower="${-100.0*toRad}" upper="${100.0*toRad}" />
    <dynamics friction="0" damping="3.0"/>
</joint>

</robot>
