<sdf version='1.6'>
  <model name='walkman'>
    <link name='base_link'>
      <pose frame=''>0 0 0 0 -0 0</pose>
      <inertial>
        <pose frame=''>0.027083 -5e-06 -0.063344 0 -0 0</pose>
        <mass>2.94591</mass>
        <inertia>
          <ixx>0.0260225</ixx>
          <ixy>9.50014e-06</ixy>
          <ixz>0.004336</ixz>
          <iyy>0.0252669</iyy>
          <iyz>4.5312e-06</iyz>
          <izz>0.0249309</izz>
        </inertia>
      </inertial>
      <collision name='base_link_fixed_joint_lump__Waist_collision'>
        <pose frame=''>0 0 0 0 -0 0</pose>
        <geometry>
          <mesh>
            <scale>0.001 0.001 0.001</scale>
            <uri>model://walkman_urdf/meshes/simple/Waist.STL</uri>
          </mesh>
        </geometry>
      </collision>
      <visual name='base_link_fixed_joint_lump__Waist_visual'>
        <pose frame=''>0 0 0 0 -0 0</pose>
        <geometry>
          <mesh>
            <scale>0.001 0.001 0.001</scale>
            <uri>model://walkman_urdf/meshes/Waist.STL</uri>
          </mesh>
        </geometry>
      </visual>
      <visual name='base_link_fixed_joint_lump__imu_link_visual_1'>
        <pose frame=''>0.0535 0 0.0601 0 -0 0</pose>
        <geometry>
          <box>
            <size>0.01 0.01 0.01</size>
          </box>
        </geometry>
        <material>
          <script>
            <uri>__default__</uri>
            <name>__default__</name>
          </script>
        </material>
      </visual>
      <visual name='base_link_fixed_joint_lump__imu_link2_visual_2'>
        <pose frame=''>0.0135 0 0.0601 0 -0 0</pose>
        <geometry>
          <box>
            <size>0.01 0.01 0.01</size>
          </box>
        </geometry>
        <material>
          <script>
            <uri>__default__</uri>
            <name>__default__</name>
          </script>
        </material>
      </visual>
      <velocity_decay/>
      <velocity_decay/>
      <sensor name='imu_link' type='imu'>
        <always_on>1</always_on>
        <update_rate>1000</update_rate>
        <visualize>1</visualize>
        <topic>__default_topic__</topic>
        <imu>
          <angular_velocity/>
          <linear_acceleration/>
        </imu>
        <pose frame=''>0.0535 0 0.0601 0 -0 0</pose>
      </sensor>
      <gravity>1</gravity>
      <velocity_decay/>
      <sensor name='imu_link2' type='imu'>
        <always_on>1</always_on>
        <update_rate>1000</update_rate>
        <visualize>1</visualize>
        <topic>__default_topic__</topic>
        <imu>
          <angular_velocity/>
          <linear_acceleration/>
        </imu>
        <pose frame=''>0.0135 0 0.0601 0 -0 0</pose>
      </sensor>
    </link>
    <link name='LHipMot'>
      <pose frame=''>0.1569 0.06 -0.108 0 -0 0</pose>
      <inertial>
        <pose frame=''>-0.103482 0.109198 -0.064924 0 -0 0</pose>
        <mass>3.79582</mass>
        <inertia>
          <ixx>0.015639</ixx>
          <ixy>-0.00185047</ixy>
          <ixz>0.00239078</ixz>
          <iyy>0.0235197</iyy>
          <iyz>0.00233032</iyz>
          <izz>0.0209536</izz>
        </inertia>
      </inertial>
      <collision name='LHipMot_collision'>
        <pose frame=''>0 0 0 0 -0 0</pose>
        <geometry>
          <mesh>
            <scale>0.001 -0.001 0.001</scale>
            <uri>model://walkman_urdf/meshes/simple/HipRoll.STL</uri>
          </mesh>
        </geometry>
        <surface>
          <contact>
            <ode/>
          </contact>
          <friction>
            <ode/>
          </friction>
        </surface>
      </collision>
      <visual name='LHipMot_visual'>
        <pose frame=''>0 0 0 0 -0 0</pose>
        <geometry>
          <mesh>
            <scale>0.001 -0.001 0.001</scale>
            <uri>model://walkman_urdf/meshes/HipRoll.STL</uri>
          </mesh>
        </geometry>
        <material>
          <script>
            <name>Gazebo/DarkGrey</name>
            <uri>file://media/materials/scripts/gazebo.material</uri>
          </script>
        </material>
      </visual>
      <gravity>1</gravity>
      <velocity_decay/>
    </link>
    <joint name='LHipLat' type='revolute'>
      <child>LHipMot</child>
      <parent>base_link</parent>
      <axis>
        <xyz>1 0 0</xyz>
        <limit>
          <lower>-0.698132</lower>
          <upper>0.872665</upper>
          <effort>400</effort>
          <velocity>6.283</velocity>
        </limit>
        <dynamics>
          <damping>3</damping>
          <friction>0</friction>
          <spring_reference>0</spring_reference>
          <spring_stiffness>0</spring_stiffness>
        </dynamics>
        <use_parent_model_frame>1</use_parent_model_frame>
      </axis>
      <physics>
        <provide_feedback>1</provide_feedback>
        <ode>
          <provide_feedback>1</provide_feedback>
          <implicit_spring_damper>1</implicit_spring_damper>
          <cfm_damping>1</cfm_damping>
          <limit>
            <cfm>0</cfm>
            <erp>0.2</erp>
          </limit>
        </ode>
      </physics>
    </joint>
    <link name='LThighUpLeg'>
      <pose frame=''>0.068 0.181032 -0.325872 0 -0 0</pose>
      <inertial>
        <pose frame=''>-0.005293 0.022562 0.00567 0 -0 0</pose>
        <mass>3.24021</mass>
        <inertia>
          <ixx>0.0101021</ixx>
          <ixy>-0.000108585</ixy>
          <ixz>0.000252914</ixz>
          <iyy>0.0067147</iyy>
          <iyz>-8.34471e-05</iyz>
          <izz>0.0104851</izz>
        </inertia>
      </inertial>
      <collision name='LThighUpLeg_collision'>
        <pose frame=''>0 0 0 0 -0 0</pose>
        <geometry>
          <mesh>
            <scale>0.001 -0.001 0.001</scale>
            <uri>model://walkman_urdf/meshes/simple/HipYaw.STL</uri>
          </mesh>
        </geometry>
        <surface>
          <contact>
            <ode/>
          </contact>
          <friction>
            <ode/>
          </friction>
        </surface>
      </collision>
      <visual name='LThighUpLeg_visual'>
        <pose frame=''>0 0 0 0 -0 0</pose>
        <geometry>
          <mesh>
            <scale>0.001 -0.001 0.001</scale>
            <uri>model://walkman_urdf/meshes/HipYaw.STL</uri>
          </mesh>
        </geometry>
        <material>
          <script>
            <name>Gazebo/DarkGrey</name>
            <uri>file://media/materials/scripts/gazebo.material</uri>
          </script>
        </material>
      </visual>
      <gravity>1</gravity>
      <velocity_decay/>
    </link>
    <joint name='LHipYaw' type='revolute'>
      <child>LThighUpLeg</child>
      <parent>LHipMot</parent>
      <axis>
        <xyz>0 0 1</xyz>
        <limit>
          <lower>-0.872665</lower>
          <upper>1.5708</upper>
          <effort>140</effort>
          <velocity>6.283</velocity>
        </limit>
        <dynamics>
          <damping>3</damping>
          <friction>0</friction>
          <spring_reference>0</spring_reference>
          <spring_stiffness>0</spring_stiffness>
        </dynamics>
        <use_parent_model_frame>1</use_parent_model_frame>
      </axis>
      <physics>
        <provide_feedback>1</provide_feedback>
        <ode>
          <provide_feedback>1</provide_feedback>
          <implicit_spring_damper>1</implicit_spring_damper>
          <cfm_damping>1</cfm_damping>
          <limit>
            <cfm>0</cfm>
            <erp>0.2</erp>
          </limit>
        </ode>
      </physics>
    </joint>
    <link name='LThighLowLeg'>
      <pose frame=''>0.068 0.181032 -0.325872 0 -0 0</pose>
      <inertial>
        <pose frame=''>0.037746 0.02854 -0.193101 0 -0 0</pose>
        <mass>5.09507</mass>
        <inertia>
          <ixx>0.0516079</ixx>
          <ixy>-0.00222535</ixy>
          <ixz>0.00245298</ixz>
          <iyy>0.0443492</iyy>
          <iyz>0.00410069</iyz>
          <izz>0.0233745</izz>
        </inertia>
      </inertial>
      <collision name='LThighLowLeg_collision'>
        <pose frame=''>0 0 0 0 -0 0</pose>
        <geometry>
          <mesh>
            <scale>0.001 -0.001 0.001</scale>
            <uri>model://walkman_urdf/meshes/simple/HipPitch.STL</uri>
          </mesh>
        </geometry>
        <surface>
          <contact>
            <ode/>
          </contact>
          <friction>
            <ode/>
          </friction>
        </surface>
      </collision>
      <visual name='LThighLowLeg_visual'>
        <pose frame=''>0 0 0 0 -0 0</pose>
        <geometry>
          <mesh>
            <scale>0.001 -0.001 0.001</scale>
            <uri>model://walkman_urdf/meshes/HipPitch.STL</uri>
          </mesh>
        </geometry>
        <material>
          <script>
            <name>Gazebo/Grey</name>
            <uri>file://media/materials/scripts/gazebo.material</uri>
          </script>
        </material>
      </visual>
      <gravity>1</gravity>
      <velocity_decay/>
    </link>
    <joint name='LHipSag' type='revolute'>
      <child>LThighLowLeg</child>
      <parent>LThighUpLeg</parent>
      <axis>
        <xyz>0 1 0</xyz>
        <limit>
          <lower>-2.0944</lower>
          <upper>1.0472</upper>
          <effort>400</effort>
          <velocity>6.283</velocity>
        </limit>
        <dynamics>
          <damping>3</damping>
          <friction>0</friction>
          <spring_reference>0</spring_reference>
          <spring_stiffness>0</spring_stiffness>
        </dynamics>
        <use_parent_model_frame>1</use_parent_model_frame>
      </axis>
      <physics>
        <provide_feedback>1</provide_feedback>
        <ode>
          <provide_feedback>1</provide_feedback>
          <implicit_spring_damper>1</implicit_spring_damper>
          <cfm_damping>1</cfm_damping>
          <limit>
            <cfm>0</cfm>
            <erp>0.2</erp>
          </limit>
        </ode>
      </physics>
    </joint>
    <link name='LLowLeg'>
      <pose frame=''>0.068 0.181032 -0.681872 0 -0 0</pose>
      <inertial>
        <pose frame=''>-0.005083 -0.003773 -0.072605 0 -0 0</pose>
        <mass>5.64953</mass>
        <inertia>
          <ixx>0.105355</ixx>
          <ixy>0.000581992</ixy>
          <ixz>0.00167436</ixz>
          <iyy>0.0978578</iyy>
          <iyz>0.00337702</iyz>
          <izz>0.0208541</izz>
        </inertia>
      </inertial>
      <collision name='LLowLeg_collision'>
        <pose frame=''>0 0 0 0 -0 0</pose>
        <geometry>
          <mesh>
            <scale>0.001 -0.001 0.001</scale>
            <uri>model://walkman_urdf/meshes/simple/KneePitchCalf.STL</uri>
          </mesh>
        </geometry>
        <surface>
          <contact>
            <ode/>
          </contact>
          <friction>
            <ode/>
          </friction>
        </surface>
      </collision>
      <visual name='LLowLeg_visual'>
        <pose frame=''>0 0 0 0 -0 0</pose>
        <geometry>
          <mesh>
            <scale>0.001 -0.001 0.001</scale>
            <uri>model://walkman_urdf/meshes/KneePitchCalf.STL</uri>
          </mesh>
        </geometry>
        <material>
          <script>
            <name>Gazebo/DarkGrey</name>
            <uri>file://media/materials/scripts/gazebo.material</uri>
          </script>
        </material>
      </visual>
      <gravity>1</gravity>
      <velocity_decay/>
    </link>
    <joint name='LKneeSag' type='revolute'>
      <child>LLowLeg</child>
      <parent>LThighLowLeg</parent>
      <axis>
        <xyz>0 1 0</xyz>
        <limit>
          <lower>0</lower>
          <upper>2.44346</upper>
          <effort>400</effort>
          <velocity>6.283</velocity>
        </limit>
        <dynamics>
          <damping>3</damping>
          <friction>0</friction>
          <spring_reference>0</spring_reference>
          <spring_stiffness>0</spring_stiffness>
        </dynamics>
        <use_parent_model_frame>1</use_parent_model_frame>
      </axis>
      <physics>
        <provide_feedback>1</provide_feedback>
        <ode>
          <provide_feedback>1</provide_feedback>
          <implicit_spring_damper>1</implicit_spring_damper>
          <cfm_damping>1</cfm_damping>
          <limit>
            <cfm>0</cfm>
            <erp>0.2</erp>
          </limit>
        </ode>
      </physics>
    </joint>
    <link name='LFootmot'>
      <pose frame=''>0.068 0.181032 -1.08187 0 -0 0</pose>
      <inertial>
        <pose frame=''>-0.022024 -0.002568 0.000946 0 -0 0</pose>
        <mass>3.28442</mass>
        <inertia>
          <ixx>0.00755507</ixx>
          <ixy>-0.000674883</ixy>
          <ixz>5.83329e-05</ixz>
          <iyy>0.0112412</iyy>
          <iyz>0.000145521</iyz>
          <izz>0.0133919</izz>
        </inertia>
      </inertial>
      <collision name='LFootmot_collision'>
        <pose frame=''>0 0 0 0 -0 0</pose>
        <geometry>
          <mesh>
            <scale>0.001 -0.001 0.001</scale>
            <uri>model://walkman_urdf/meshes/simple/AnklePitch.STL</uri>
          </mesh>
        </geometry>
        <surface>
          <contact>
            <ode/>
          </contact>
          <friction>
            <ode/>
          </friction>
        </surface>
      </collision>
      <visual name='LFootmot_visual'>
        <pose frame=''>0 0 0 0 -0 0</pose>
        <geometry>
          <mesh>
            <scale>0.001 -0.001 0.001</scale>
            <uri>model://walkman_urdf/meshes/AnklePitch.STL</uri>
          </mesh>
        </geometry>
        <material>
          <script>
            <name>Gazebo/DarkGrey</name>
            <uri>file://media/materials/scripts/gazebo.material</uri>
          </script>
        </material>
      </visual>
      <gravity>1</gravity>
      <velocity_decay/>
    </link>
    <joint name='LAnkSag' type='revolute'>
      <child>LFootmot</child>
      <parent>LLowLeg</parent>
      <axis>
        <xyz>0 1 0</xyz>
        <limit>
          <lower>-1.39626</lower>
          <upper>0.698132</upper>
          <effort>330</effort>
          <velocity>6.283</velocity>
        </limit>
        <dynamics>
          <damping>3</damping>
          <friction>0</friction>
          <spring_reference>0</spring_reference>
          <spring_stiffness>0</spring_stiffness>
        </dynamics>
        <use_parent_model_frame>1</use_parent_model_frame>
      </axis>
      <physics>
        <provide_feedback>1</provide_feedback>
        <ode>
          <provide_feedback>1</provide_feedback>
          <implicit_spring_damper>1</implicit_spring_damper>
          <cfm_damping>1</cfm_damping>
          <limit>
            <cfm>0</cfm>
            <erp>0.2</erp>
          </limit>
        </ode>
      </physics>
    </joint>
    <link name='LFoot'>
      <pose frame=''>0.068 0.181032 -1.08187 0 -0 0</pose>
      <inertial>
        <pose frame=''>-0.006536 0.004794 -0.101804 0 -0 0</pose>
        <mass>3.42638</mass>
        <inertia>
          <ixx>0.0103289</ixx>
          <ixy>0.00016407</ixy>
          <ixz>-0.00201294</ixz>
          <iyy>0.0285402</iyy>
          <iyz>-0.00046315</iyz>
          <izz>0.027995</izz>
        </inertia>
      </inertial>
      <collision name='LFoot_collision'>
        <pose frame=''>0.005 0.01 -0.1359 0 -0 0</pose>
        <geometry>
          <box>
            <size>0.32 0.16 0.015</size>
          </box>
        </geometry>
        <surface>
          <contact>
            <ode>
              <kp>1e+06</kp>
              <kd>100</kd>
              <max_vel>1</max_vel>
              <min_depth>0</min_depth>
            </ode>
          </contact>
          <friction>
            <ode>
              <mu>1</mu>
              <mu2>1</mu2>
              <fdir1>1 0 0</fdir1>
            </ode>
          </friction>
        </surface>
      </collision>
      <visual name='LFoot_visual'>
        <pose frame=''>0 0 0 0 -0 0</pose>
        <geometry>
          <mesh>
            <scale>0.001 -0.001 0.001</scale>
            <uri>model://walkman_urdf/meshes/Foot.STL</uri>
          </mesh>
        </geometry>
        <material>
          <script>
            <name>Gazebo/DarkGrey</name>
            <uri>file://media/materials/scripts/gazebo.material</uri>
          </script>
        </material>
      </visual>
      <velocity_decay/>
      <gravity>1</gravity>
      <velocity_decay/>
    </link>
    <joint name='LAnkLat' type='revolute'>
      <child>LFoot</child>
      <parent>LFootmot</parent>
      <axis>
        <xyz>1 0 0</xyz>
        <limit>
          <lower>-0.785398</lower>
          <upper>0.785398</upper>
          <effort>210</effort>
          <velocity>6.283</velocity>
        </limit>
        <dynamics>
          <damping>3</damping>
          <friction>0</friction>
          <spring_reference>0</spring_reference>
          <spring_stiffness>0</spring_stiffness>
        </dynamics>
        <use_parent_model_frame>1</use_parent_model_frame>
      </axis>
      <physics>
        <ode>
          <limit>
            <cfm>0</cfm>
            <erp>0.2</erp>
          </limit>
          <provide_feedback>1</provide_feedback>
          <implicit_spring_damper>1</implicit_spring_damper>
          <cfm_damping>1</cfm_damping>
        </ode>
        <provide_feedback>1</provide_feedback>
      </physics>
      <sensor name='l_leg_ft' type='force_torque'>
        <force_torque>
          <frame>sensor</frame>
          <measure_direction>child_to_parent</measure_direction>
        </force_torque>
        <always_on>1</always_on>
        <visualize>1</visualize>
        <update_rate>1000</update_rate>
        <pose frame=''>0.005 0 -0.107 0 -0 0</pose>
      </sensor>
    </joint>
    <link name='RHipMot'>
      <pose frame=''>0.1569 -0.06 -0.108 0 -0 0</pose>
      <inertial>
        <pose frame=''>-0.103482 -0.109198 -0.064924 0 -0 0</pose>
        <mass>3.79582</mass>
        <inertia>
          <ixx>0.015639</ixx>
          <ixy>0.00185047</ixy>
          <ixz>0.00239078</ixz>
          <iyy>0.0235197</iyy>
          <iyz>-0.00233032</iyz>
          <izz>0.0209536</izz>
        </inertia>
      </inertial>
      <collision name='RHipMot_collision'>
        <pose frame=''>0 0 0 0 -0 0</pose>
        <geometry>
          <mesh>
            <scale>0.001 0.001 0.001</scale>
            <uri>model://walkman_urdf/meshes/simple/HipRoll.STL</uri>
          </mesh>
        </geometry>
        <surface>
          <contact>
            <ode/>
          </contact>
          <friction>
            <ode/>
          </friction>
        </surface>
      </collision>
      <visual name='RHipMot_visual'>
        <pose frame=''>0 0 0 0 -0 0</pose>
        <geometry>
          <mesh>
            <scale>0.001 0.001 0.001</scale>
            <uri>model://walkman_urdf/meshes/HipRoll.STL</uri>
          </mesh>
        </geometry>
        <material>
          <script>
            <name>Gazebo/DarkGrey</name>
            <uri>file://media/materials/scripts/gazebo.material</uri>
          </script>
        </material>
      </visual>
      <gravity>1</gravity>
      <velocity_decay/>
    </link>
    <joint name='RHipLat' type='revolute'>
      <child>RHipMot</child>
      <parent>base_link</parent>
      <axis>
        <xyz>1 0 0</xyz>
        <limit>
          <lower>-0.872665</lower>
          <upper>0.698132</upper>
          <effort>400</effort>
          <velocity>6.283</velocity>
        </limit>
        <dynamics>
          <damping>3</damping>
          <friction>0</friction>
          <spring_reference>0</spring_reference>
          <spring_stiffness>0</spring_stiffness>
        </dynamics>
        <use_parent_model_frame>1</use_parent_model_frame>
      </axis>
      <physics>
        <provide_feedback>1</provide_feedback>
        <ode>
          <provide_feedback>1</provide_feedback>
          <implicit_spring_damper>1</implicit_spring_damper>
          <cfm_damping>1</cfm_damping>
          <limit>
            <cfm>0</cfm>
            <erp>0.2</erp>
          </limit>
        </ode>
      </physics>
    </joint>
    <link name='RThighUpLeg'>
      <pose frame=''>0.068 -0.181032 -0.325872 0 -0 0</pose>
      <inertial>
        <pose frame=''>-0.005293 -0.022562 0.00567 0 -0 0</pose>
        <mass>3.24021</mass>
        <inertia>
          <ixx>0.0101021</ixx>
          <ixy>0.000108585</ixy>
          <ixz>0.000252914</ixz>
          <iyy>0.0067147</iyy>
          <iyz>8.34471e-05</iyz>
          <izz>0.0104851</izz>
        </inertia>
      </inertial>
      <collision name='RThighUpLeg_collision'>
        <pose frame=''>0 0 0 0 -0 0</pose>
        <geometry>
          <mesh>
            <scale>0.001 0.001 0.001</scale>
            <uri>model://walkman_urdf/meshes/simple/HipYaw.STL</uri>
          </mesh>
        </geometry>
        <surface>
          <contact>
            <ode/>
          </contact>
          <friction>
            <ode/>
          </friction>
        </surface>
      </collision>
      <visual name='RThighUpLeg_visual'>
        <pose frame=''>0 0 0 0 -0 0</pose>
        <geometry>
          <mesh>
            <scale>0.001 0.001 0.001</scale>
            <uri>model://walkman_urdf/meshes/HipYaw.STL</uri>
          </mesh>
        </geometry>
        <material>
          <script>
            <name>Gazebo/DarkGrey</name>
            <uri>file://media/materials/scripts/gazebo.material</uri>
          </script>
        </material>
      </visual>
      <gravity>1</gravity>
      <velocity_decay/>
    </link>
    <joint name='RHipYaw' type='revolute'>
      <child>RThighUpLeg</child>
      <parent>RHipMot</parent>
      <axis>
        <xyz>0 0 1</xyz>
        <limit>
          <lower>-1.5708</lower>
          <upper>0.872665</upper>
          <effort>140</effort>
          <velocity>6.283</velocity>
        </limit>
        <dynamics>
          <damping>3</damping>
          <friction>0</friction>
          <spring_reference>0</spring_reference>
          <spring_stiffness>0</spring_stiffness>
        </dynamics>
        <use_parent_model_frame>1</use_parent_model_frame>
      </axis>
      <physics>
        <provide_feedback>1</provide_feedback>
        <ode>
          <provide_feedback>1</provide_feedback>
          <implicit_spring_damper>1</implicit_spring_damper>
          <cfm_damping>1</cfm_damping>
          <limit>
            <cfm>0</cfm>
            <erp>0.2</erp>
          </limit>
        </ode>
      </physics>
    </joint>
    <link name='RThighLowLeg'>
      <pose frame=''>0.068 -0.181032 -0.325872 0 -0 0</pose>
      <inertial>
        <pose frame=''>0.037746 -0.02854 -0.193101 0 -0 0</pose>
        <mass>5.09507</mass>
        <inertia>
          <ixx>0.0516079</ixx>
          <ixy>0.00222535</ixy>
          <ixz>0.00245298</ixz>
          <iyy>0.0443492</iyy>
          <iyz>-0.00410069</iyz>
          <izz>0.0233745</izz>
        </inertia>
      </inertial>
      <collision name='RThighLowLeg_collision'>
        <pose frame=''>0 0 0 0 -0 0</pose>
        <geometry>
          <mesh>
            <scale>0.001 0.001 0.001</scale>
            <uri>model://walkman_urdf/meshes/simple/HipPitch.STL</uri>
          </mesh>
        </geometry>
        <surface>
          <contact>
            <ode/>
          </contact>
          <friction>
            <ode/>
          </friction>
        </surface>
      </collision>
      <visual name='RThighLowLeg_visual'>
        <pose frame=''>0 0 0 0 -0 0</pose>
        <geometry>
          <mesh>
            <scale>0.001 0.001 0.001</scale>
            <uri>model://walkman_urdf/meshes/HipPitch.STL</uri>
          </mesh>
        </geometry>
        <material>
          <script>
            <name>Gazebo/Grey</name>
            <uri>file://media/materials/scripts/gazebo.material</uri>
          </script>
        </material>
      </visual>
      <gravity>1</gravity>
      <velocity_decay/>
    </link>
    <joint name='RHipSag' type='revolute'>
      <child>RThighLowLeg</child>
      <parent>RThighUpLeg</parent>
      <axis>
        <xyz>0 1 0</xyz>
        <limit>
          <lower>-2.0944</lower>
          <upper>1.0472</upper>
          <effort>400</effort>
          <velocity>6.283</velocity>
        </limit>
        <dynamics>
          <damping>3</damping>
          <friction>0</friction>
          <spring_reference>0</spring_reference>
          <spring_stiffness>0</spring_stiffness>
        </dynamics>
        <use_parent_model_frame>1</use_parent_model_frame>
      </axis>
      <physics>
        <provide_feedback>1</provide_feedback>
        <ode>
          <provide_feedback>1</provide_feedback>
          <implicit_spring_damper>1</implicit_spring_damper>
          <cfm_damping>1</cfm_damping>
          <limit>
            <cfm>0</cfm>
            <erp>0.2</erp>
          </limit>
        </ode>
      </physics>
    </joint>
    <link name='RLowLeg'>
      <pose frame=''>0.068 -0.181032 -0.681872 0 -0 0</pose>
      <inertial>
        <pose frame=''>-0.005083 0.003773 -0.072605 0 -0 0</pose>
        <mass>5.64953</mass>
        <inertia>
          <ixx>0.105355</ixx>
          <ixy>-0.000581992</ixy>
          <ixz>0.00167436</ixz>
          <iyy>0.0978578</iyy>
          <iyz>-0.00337702</iyz>
          <izz>0.0208541</izz>
        </inertia>
      </inertial>
      <collision name='RLowLeg_collision'>
        <pose frame=''>0 0 0 0 -0 0</pose>
        <geometry>
          <mesh>
            <scale>0.001 0.001 0.001</scale>
            <uri>model://walkman_urdf/meshes/simple/KneePitchCalf.STL</uri>
          </mesh>
        </geometry>
        <surface>
          <contact>
            <ode/>
          </contact>
          <friction>
            <ode/>
          </friction>
        </surface>
      </collision>
      <visual name='RLowLeg_visual'>
        <pose frame=''>0 0 0 0 -0 0</pose>
        <geometry>
          <mesh>
            <scale>0.001 0.001 0.001</scale>
            <uri>model://walkman_urdf/meshes/KneePitchCalf.STL</uri>
          </mesh>
        </geometry>
        <material>
          <script>
            <name>Gazebo/DarkGrey</name>
            <uri>file://media/materials/scripts/gazebo.material</uri>
          </script>
        </material>
      </visual>
      <gravity>1</gravity>
      <velocity_decay/>
    </link>
    <joint name='RKneeSag' type='revolute'>
      <child>RLowLeg</child>
      <parent>RThighLowLeg</parent>
      <axis>
        <xyz>0 1 0</xyz>
        <limit>
          <lower>0</lower>
          <upper>2.44346</upper>
          <effort>400</effort>
          <velocity>6.283</velocity>
        </limit>
        <dynamics>
          <damping>3</damping>
          <friction>0</friction>
          <spring_reference>0</spring_reference>
          <spring_stiffness>0</spring_stiffness>
        </dynamics>
        <use_parent_model_frame>1</use_parent_model_frame>
      </axis>
      <physics>
        <provide_feedback>1</provide_feedback>
        <ode>
          <provide_feedback>1</provide_feedback>
          <implicit_spring_damper>1</implicit_spring_damper>
          <cfm_damping>1</cfm_damping>
          <limit>
            <cfm>0</cfm>
            <erp>0.2</erp>
          </limit>
        </ode>
      </physics>
    </joint>
    <link name='RFootmot'>
      <pose frame=''>0.068 -0.181032 -1.08187 0 -0 0</pose>
      <inertial>
        <pose frame=''>-0.022024 0.002568 0.000946 0 -0 0</pose>
        <mass>3.28442</mass>
        <inertia>
          <ixx>0.00755507</ixx>
          <ixy>0.000674883</ixy>
          <ixz>5.83329e-05</ixz>
          <iyy>0.0112412</iyy>
          <iyz>-0.000145521</iyz>
          <izz>0.0133919</izz>
        </inertia>
      </inertial>
      <collision name='RFootmot_collision'>
        <pose frame=''>0 0 0 0 -0 0</pose>
        <geometry>
          <mesh>
            <scale>0.001 0.001 0.001</scale>
            <uri>model://walkman_urdf/meshes/simple/AnklePitch.STL</uri>
          </mesh>
        </geometry>
        <surface>
          <contact>
            <ode/>
          </contact>
          <friction>
            <ode/>
          </friction>
        </surface>
      </collision>
      <visual name='RFootmot_visual'>
        <pose frame=''>0 0 0 0 -0 0</pose>
        <geometry>
          <mesh>
            <scale>0.001 0.001 0.001</scale>
            <uri>model://walkman_urdf/meshes/AnklePitch.STL</uri>
          </mesh>
        </geometry>
        <material>
          <script>
            <name>Gazebo/DarkGrey</name>
            <uri>file://media/materials/scripts/gazebo.material</uri>
          </script>
        </material>
      </visual>
      <gravity>1</gravity>
      <velocity_decay/>
    </link>
    <joint name='RAnkSag' type='revolute'>
      <child>RFootmot</child>
      <parent>RLowLeg</parent>
      <axis>
        <xyz>0 1 0</xyz>
        <limit>
          <lower>-1.39626</lower>
          <upper>0.698132</upper>
          <effort>330</effort>
          <velocity>6.283</velocity>
        </limit>
        <dynamics>
          <damping>3</damping>
          <friction>0</friction>
          <spring_reference>0</spring_reference>
          <spring_stiffness>0</spring_stiffness>
        </dynamics>
        <use_parent_model_frame>1</use_parent_model_frame>
      </axis>
      <physics>
        <provide_feedback>1</provide_feedback>
        <ode>
          <provide_feedback>1</provide_feedback>
          <implicit_spring_damper>1</implicit_spring_damper>
          <cfm_damping>1</cfm_damping>
          <limit>
            <cfm>0</cfm>
            <erp>0.2</erp>
          </limit>
        </ode>
      </physics>
    </joint>
    <link name='RFoot'>
      <pose frame=''>0.068 -0.181032 -1.08187 0 -0 0</pose>
      <inertial>
        <pose frame=''>-0.006536 -0.004794 -0.101804 0 -0 0</pose>
        <mass>3.42638</mass>
        <inertia>
          <ixx>0.0103289</ixx>
          <ixy>-0.00016407</ixy>
          <ixz>-0.00201294</ixz>
          <iyy>0.0285402</iyy>
          <iyz>0.00046315</iyz>
          <izz>0.027995</izz>
        </inertia>
      </inertial>
      <collision name='RFoot_collision'>
        <pose frame=''>0.005 -0.01 -0.1359 0 -0 0</pose>
        <geometry>
          <box>
            <size>0.32 0.16 0.015</size>
          </box>
        </geometry>
        <surface>
          <contact>
            <ode>
              <kp>1e+06</kp>
              <kd>100</kd>
              <max_vel>1</max_vel>
              <min_depth>0</min_depth>
            </ode>
          </contact>
          <friction>
            <ode>
              <mu>1</mu>
              <mu2>1</mu2>
              <fdir1>1 0 0</fdir1>
            </ode>
          </friction>
        </surface>
      </collision>
      <visual name='RFoot_visual'>
        <pose frame=''>0 0 0 0 -0 0</pose>
        <geometry>
          <mesh>
            <scale>0.001 0.001 0.001</scale>
            <uri>model://walkman_urdf/meshes/Foot.STL</uri>
          </mesh>
        </geometry>
        <material>
          <script>
            <name>Gazebo/DarkGrey</name>
            <uri>file://media/materials/scripts/gazebo.material</uri>
          </script>
        </material>
      </visual>
      <velocity_decay/>
      <gravity>1</gravity>
      <velocity_decay/>
    </link>
    <joint name='RAnkLat' type='revolute'>
      <child>RFoot</child>
      <parent>RFootmot</parent>
      <axis>
        <xyz>1 0 0</xyz>
        <limit>
          <lower>-0.785398</lower>
          <upper>0.785398</upper>
          <effort>210</effort>
          <velocity>6.283</velocity>
        </limit>
        <dynamics>
          <damping>3</damping>
          <friction>0</friction>
          <spring_reference>0</spring_reference>
          <spring_stiffness>0</spring_stiffness>
        </dynamics>
        <use_parent_model_frame>1</use_parent_model_frame>
      </axis>
      <physics>
        <ode>
          <limit>
            <cfm>0</cfm>
            <erp>0.2</erp>
          </limit>
          <provide_feedback>1</provide_feedback>
          <implicit_spring_damper>1</implicit_spring_damper>
          <cfm_damping>1</cfm_damping>
        </ode>
        <provide_feedback>1</provide_feedback>
      </physics>
      <sensor name='r_leg_ft' type='force_torque'>
        <force_torque>
          <frame>sensor</frame>
          <measure_direction>child_to_parent</measure_direction>
        </force_torque>
        <always_on>1</always_on>
        <visualize>1</visualize>
        <update_rate>1000</update_rate>
        <pose frame=''>0.005 0 -0.107 0 -0 0</pose>
      </sensor>
    </joint>
    <link name='DWL'>
      <pose frame=''>0.0596 0 0 0 -0 0</pose>
      <inertial>
        <pose frame=''>-0.013439 -2.5e-05 0.073563 0 -0 0</pose>
        <mass>2.43091</mass>
        <inertia>
          <ixx>0.0167028</ixx>
          <ixy>3.59082e-05</ixy>
          <ixz>-0.00417093</ixz>
          <iyy>0.0194409</iyy>
          <iyz>1.1578e-05</iyz>
          <izz>0.00577211</izz>
        </inertia>
      </inertial>
      <collision name='DWL_collision'>
        <pose frame=''>0 0 0 0 -0 0</pose>
        <geometry>
          <mesh>
            <scale>0.001 0.001 0.001</scale>
            <uri>model://walkman_urdf/meshes/simple/TorsoRoll.STL</uri>
          </mesh>
        </geometry>
        <surface>
          <contact>
            <ode/>
          </contact>
          <friction>
            <ode/>
          </friction>
        </surface>
      </collision>
      <visual name='DWL_visual'>
        <pose frame=''>0 0 0 0 -0 0</pose>
        <geometry>
          <mesh>
            <scale>0.001 0.001 0.001</scale>
            <uri>model://walkman_urdf/meshes/TorsoRoll.STL</uri>
          </mesh>
        </geometry>
        <material>
          <script>
            <name>Gazebo/DarkGrey</name>
            <uri>file://media/materials/scripts/gazebo.material</uri>
          </script>
        </material>
      </visual>
      <gravity>1</gravity>
      <velocity_decay/>
    </link>
    <joint name='WaistLat' type='revolute'>
      <child>DWL</child>
      <parent>base_link</parent>
      <axis>
        <xyz>1 0 0</xyz>
        <limit>
          <lower>-0.610865</lower>
          <upper>0.610865</upper>
          <effort>120</effort>
          <velocity>6.283</velocity>
        </limit>
        <dynamics>
          <damping>3</damping>
          <friction>0</friction>
          <spring_reference>0</spring_reference>
          <spring_stiffness>0</spring_stiffness>
        </dynamics>
        <use_parent_model_frame>1</use_parent_model_frame>
      </axis>
    </joint>
    <link name='DWYTorso'>
      <pose frame=''>0.0684 0 0.22215 0 -0 0</pose>
      <inertial>
        <pose frame=''>-0.059646 0.001431 0.042742 0 -0 0</pose>
        <mass>12.5123</mass>
        <inertia>
          <ixx>0.210216</ixx>
          <ixy>-0.000155272</ixy>
          <ixz>-0.0502166</ixz>
          <iyy>0.19983</iyy>
          <iyz>-0.000292048</iyz>
          <izz>0.140251</izz>
        </inertia>
      </inertial>
      <collision name='DWYTorso_collision'>
        <pose frame=''>0 0 0 0 -0 0</pose>
        <geometry>
          <mesh>
            <scale>0.001 0.001 0.001</scale>
            <uri>model://walkman_urdf/meshes/simple/Chest.STL</uri>
          </mesh>
        </geometry>
        <surface>
          <contact>
            <ode/>
          </contact>
          <friction>
            <ode/>
          </friction>
        </surface>
      </collision>
      <visual name='DWYTorso_visual'>
        <pose frame=''>0 0 0 0 -0 0</pose>
        <geometry>
          <mesh>
            <scale>0.001 0.001 0.001</scale>
            <uri>model://walkman_urdf/meshes/Chest.STL</uri>
          </mesh>
        </geometry>
        <material>
          <script>
            <name>Gazebo/Blue</name>
            <uri>file://media/materials/scripts/gazebo.material</uri>
          </script>
        </material>
      </visual>
      <gravity>1</gravity>
      <velocity_decay/>
    </link>
    <joint name='WaistYaw' type='revolute'>
      <child>DWYTorso</child>
      <parent>DWL</parent>
      <axis>
        <xyz>0 0 1</xyz>
        <limit>
          <lower>-1.74533</lower>
          <upper>1.74533</upper>
          <effort>120</effort>
          <velocity>6.283</velocity>
        </limit>
        <dynamics>
          <damping>3</damping>
          <friction>0</friction>
          <spring_reference>0</spring_reference>
          <spring_stiffness>0</spring_stiffness>
        </dynamics>
        <use_parent_model_frame>1</use_parent_model_frame>
      </axis>
      <physics>
        <provide_feedback>1</provide_feedback>
        <ode>
          <provide_feedback>1</provide_feedback>
          <implicit_spring_damper>1</implicit_spring_damper>
          <cfm_damping>1</cfm_damping>
          <limit>
            <cfm>0</cfm>
            <erp>0.2</erp>
          </limit>
        </ode>
      </physics>
    </joint>
    <link name='LShp'>
      <pose frame=''>0.114148 0.169137 0.377276 0.174533 -0 -0.523599</pose>
      <inertial>
        <pose frame=''>-0.007446 0.034108 0.00011 0 -0 0</pose>
        <mass>1.96287</mass>
        <inertia>
          <ixx>0.00535477</ixx>
          <ixy>0.000364289</ixy>
          <ixz>1.50896e-05</ixz>
          <iyy>0.00339233</iyy>
          <iyz>5.56923e-05</iyz>
          <izz>0.00689214</izz>
        </inertia>
      </inertial>
      <collision name='LShp_collision'>
        <pose frame=''>0 0 0 0 -0 0</pose>
        <geometry>
          <mesh>
            <scale>0.001 -0.001 0.001</scale>
            <uri>model://walkman_urdf/meshes/simple/ShoulderPitch.STL</uri>
          </mesh>
        </geometry>
      </collision>
      <visual name='LShp_visual'>
        <pose frame=''>0 0 0 0 -0 0</pose>
        <geometry>
          <mesh>
            <scale>0.001 -0.001 0.001</scale>
            <uri>model://walkman_urdf/meshes/ShoulderPitch.STL</uri>
          </mesh>
        </geometry>
      </visual>
    </link>
    <joint name='LShSag' type='revolute'>
      <child>LShp</child>
      <parent>DWYTorso</parent>
      <axis>
        <xyz>0.492404 0.852869 0.173648</xyz>
        <limit>
          <lower>-3.40339</lower>
          <upper>1.65806</upper>
          <effort>147</effort>
          <velocity>6.283</velocity>
        </limit>
        <dynamics>
          <damping>3</damping>
          <friction>0</friction>
          <spring_reference>0</spring_reference>
          <spring_stiffness>0</spring_stiffness>
        </dynamics>
        <use_parent_model_frame>1</use_parent_model_frame>
      </axis>
    </joint>
    <link name='LShr'>
      <pose frame=''>0.066604 0.26709 0.388042 0 0 -0.523599</pose>
      <inertial>
        <pose frame=''>0.058142 5.7e-05 -0.077478 0 -0 0</pose>
        <mass>1.85958</mass>
        <inertia>
          <ixx>0.0137766</ixx>
          <ixy>3.77887e-05</ixy>
          <ixz>0.00376902</ixz>
          <iyy>0.0156775</iyy>
          <iyz>-9.48935e-06</iyz>
          <izz>0.00463177</izz>
        </inertia>
      </inertial>
      <collision name='LShr_collision'>
        <pose frame=''>0 0 0 0 -0 0</pose>
        <geometry>
          <mesh>
            <scale>0.001 -0.001 0.001</scale>
            <uri>model://walkman_urdf/meshes/simple/ShoulderRoll.STL</uri>
          </mesh>
        </geometry>
      </collision>
      <visual name='LShr_visual'>
        <pose frame=''>0 0 0 0 -0 0</pose>
        <geometry>
          <mesh>
            <scale>0.001 -0.001 0.001</scale>
            <uri>model://walkman_urdf/meshes/ShoulderRoll.STL</uri>
          </mesh>
        </geometry>
      </visual>
    </link>
    <joint name='LShLat' type='revolute'>
      <child>LShr</child>
      <parent>LShp</parent>
      <axis>
        <xyz>0.866025 -0.5 -0</xyz>
        <limit>
          <lower>0</lower>
          <upper>3.49066</upper>
          <effort>120</effort>
          <velocity>6.283</velocity>
        </limit>
        <dynamics>
          <damping>3</damping>
          <friction>0</friction>
          <spring_reference>0</spring_reference>
          <spring_stiffness>0</spring_stiffness>
        </dynamics>
        <use_parent_model_frame>1</use_parent_model_frame>
      </axis>
    </joint>
    <link name='LShy'>
      <pose frame=''>0.144677 0.222015 0.169892 0 0 -0.523599</pose>
      <inertial>
        <pose frame=''>0.014625 0.000817 -0.028334 0 -0 0</pose>
        <mass>1.66781</mass>
        <inertia>
          <ixx>0.00644804</ixx>
          <ixy>-0.000156391</ixy>
          <ixz>0.00122054</ixz>
          <iyy>0.00733721</iyy>
          <iyz>8.99415e-05</iyz>
          <izz>0.00367384</izz>
        </inertia>
      </inertial>
      <collision name='LShy_collision'>
        <pose frame=''>0 0 0 0 -0 0</pose>
        <geometry>
          <mesh>
            <scale>0.001 -0.001 0.001</scale>
            <uri>model://walkman_urdf/meshes/simple/ShoulderYaw.STL</uri>
          </mesh>
        </geometry>
      </collision>
      <visual name='LShy_visual'>
        <pose frame=''>0 0 0 0 -0 0</pose>
        <geometry>
          <mesh>
            <scale>0.001 -0.001 0.001</scale>
            <uri>model://walkman_urdf/meshes/ShoulderYaw.STL</uri>
          </mesh>
        </geometry>
      </visual>
    </link>
    <joint name='LShYaw' type='revolute'>
      <child>LShy</child>
      <parent>LShr</parent>
      <axis>
        <xyz>-0 -0 1</xyz>
        <limit>
          <lower>-2.61799</lower>
          <upper>2.61799</upper>
          <effort>147</effort>
          <velocity>6.283</velocity>
        </limit>
        <dynamics>
          <damping>3</damping>
          <friction>0</friction>
          <spring_reference>0</spring_reference>
          <spring_stiffness>0</spring_stiffness>
        </dynamics>
        <use_parent_model_frame>1</use_parent_model_frame>
      </axis>
    </joint>
    <link name='LElb'>
      <pose frame=''>0.211223 0.247276 0.095892 0 0 -0.523599</pose>
      <inertial>
        <pose frame=''>-0.007683 -0.040302 -0.043493 0 -0 0</pose>
        <mass>1.31573</mass>
        <inertia>
          <ixx>0.00433039</ixx>
          <ixy>-0.000117374</ixy>
          <ixz>-0.000419232</ixz>
          <iyy>0.00385399</iyy>
          <iyz>-0.00079573</iyz>
          <izz>0.00175947</izz>
        </inertia>
      </inertial>
      <collision name='LElb_collision'>
        <pose frame=''>0 0 0 0 -0 0</pose>
        <geometry>
          <mesh>
            <scale>0.001 -0.001 0.001</scale>
            <uri>model://walkman_urdf/meshes/simple/Elbow.STL</uri>
          </mesh>
        </geometry>
      </collision>
      <visual name='LElb_visual'>
        <pose frame=''>0 0 0 0 -0 0</pose>
        <geometry>
          <mesh>
            <scale>0.001 -0.001 0.001</scale>
            <uri>model://walkman_urdf/meshes/Elbow.STL</uri>
          </mesh>
        </geometry>
      </visual>
    </link>
    <joint name='LElbj' type='revolute'>
      <child>LElb</child>
      <parent>LShy</parent>
      <axis>
        <xyz>0.5 0.866025 0</xyz>
        <limit>
          <lower>-2.53073</lower>
          <upper>0.349066</upper>
          <effort>147</effort>
          <velocity>6.283</velocity>
        </limit>
        <dynamics>
          <damping>3</damping>
          <friction>0</friction>
          <spring_reference>0</spring_reference>
          <spring_stiffness>0</spring_stiffness>
        </dynamics>
        <use_parent_model_frame>1</use_parent_model_frame>
      </axis>
    </joint>
    <link name='LForearm'>
      <pose frame=''>0.170657 0.207015 0.000892 0 0 -0.523599</pose>
      <inertial>
        <pose frame=''>-0.000111 0.011591 -0.07816 0 -0 0</pose>
        <mass>1.49085</mass>
        <inertia>
          <ixx>0.00856921</ixx>
          <ixy>1.78563e-05</ixy>
          <ixz>1.93794e-05</ixz>
          <iyy>0.00774542</iyy>
          <iyz>-0.000328601</iyz>
          <izz>0.00274419</izz>
        </inertia>
      </inertial>
      <collision name='LForearm_collision'>
        <pose frame=''>0 0 0 0 -0 0</pose>
        <geometry>
          <mesh>
            <scale>0.001 -0.001 0.001</scale>
            <uri>model://walkman_urdf/meshes/simple/Forearm.STL</uri>
          </mesh>
        </geometry>
      </collision>
      <visual name='LForearm_visual'>
        <pose frame=''>0 0 0 0 -0 0</pose>
        <geometry>
          <mesh>
            <scale>0.001 -0.001 0.001</scale>
            <uri>model://walkman_urdf/meshes/Forearm.STL</uri>
          </mesh>
        </geometry>
      </visual>
    </link>
    <joint name='LForearmPlate' type='revolute'>
      <child>LForearm</child>
      <parent>LElb</parent>
      <axis>
        <xyz>-0 -0 1</xyz>
        <limit>
          <lower>-2.61799</lower>
          <upper>2.61799</upper>
          <effort>55</effort>
          <velocity>6.283</velocity>
        </limit>
        <dynamics>
          <damping>0.03</damping>
          <friction>0</friction>
          <spring_reference>0</spring_reference>
          <spring_stiffness>0</spring_stiffness>
        </dynamics>
        <use_parent_model_frame>1</use_parent_model_frame>
      </axis>
    </joint>
    <link name='LWrMot2'>
      <pose frame=''>0.195157 0.24945 -0.155108 0 0 -0.523599</pose>
      <inertial>
        <pose frame=''>-5e-06 -0.038014 -0.069927 0 -0 0</pose>
        <mass>1.12636</mass>
        <inertia>
          <ixx>0.00518718</ixx>
          <ixy>2.72444e-05</ixy>
          <ixz>2.28335e-06</ixz>
          <iyy>0.00480378</iyy>
          <iyz>-0.000721657</iyz>
          <izz>0.00127714</izz>
        </inertia>
      </inertial>
      <collision name='LWrMot2_collision'>
        <pose frame=''>0 0 0 0 -0 0</pose>
        <geometry>
          <mesh>
            <scale>0.001 -0.001 0.001</scale>
            <uri>model://walkman_urdf/meshes/simple/ForearmPitch.STL</uri>
          </mesh>
        </geometry>
      </collision>
      <visual name='LWrMot2_visual'>
        <pose frame=''>0 0 0 0 -0 0</pose>
        <geometry>
          <mesh>
            <scale>0.001 -0.001 0.001</scale>
            <uri>model://walkman_urdf/meshes/ForearmPitch.STL</uri>
          </mesh>
        </geometry>
      </visual>
    </link>
    <joint name='LWrj1' type='revolute'>
      <child>LWrMot2</child>
      <parent>LForearm</parent>
      <axis>
        <xyz>0.5 0.866025 0</xyz>
        <limit>
          <lower>-1.5708</lower>
          <upper>1.5708</upper>
          <effort>55</effort>
          <velocity>6.283</velocity>
        </limit>
        <dynamics>
          <damping>0.03</damping>
          <friction>0</friction>
          <spring_reference>0</spring_reference>
          <spring_stiffness>0</spring_stiffness>
        </dynamics>
        <use_parent_model_frame>1</use_parent_model_frame>
      </axis>
    </joint>
    <link name='LWrMot3'>
      <pose frame=''>0.170657 0.207015 -0.329108 0 0 -0.523599</pose>
      <inertial>
        <pose frame=''>0 0 0.031271 0 -0 0</pose>
        <mass>0.279664</mass>
        <inertia>
          <ixx>0.000144152</ixx>
          <ixy>9.86518e-08</ixy>
          <ixz>0</ixz>
          <iyy>0.00014417</iyy>
          <iyz>0</iyz>
          <izz>6.05006e-05</izz>
        </inertia>
      </inertial>
      <collision name='LWrMot3_collision'>
        <pose frame=''>0 0 0 0 -0 0</pose>
        <geometry>
          <box>
            <size>0.1 0.1 0.01</size>
          </box>
        </geometry>
      </collision>
      <visual name='LWrMot3_visual'>
        <pose frame=''>0 0 0 0 -0 0</pose>
        <geometry>
          <box>
            <size>0.1 0.1 0.01</size>
          </box>
        </geometry>
      </visual>
    </link>
    <joint name='LWrj2' type='revolute'>
      <child>LWrMot3</child>
      <parent>LWrMot2</parent>
      <axis>
        <xyz>-0 -0 1</xyz>
        <limit>
          <lower>-2.61799</lower>
          <upper>2.61799</upper>
          <effort>27</effort>
          <velocity>6.283</velocity>
        </limit>
        <dynamics>
          <damping>0.03</damping>
          <friction>0</friction>
          <spring_reference>0</spring_reference>
          <spring_stiffness>0</spring_stiffness>
        </dynamics>
        <use_parent_model_frame>1</use_parent_model_frame>
      </axis>
    </joint>
    <link name='NeckYaw'>
      <pose frame=''>0.0844 0 0.460442 0 -0 0</pose>
      <inertial>
        <pose frame=''>0.000177 -0.00057 0.009696 0 -0 0</pose>
        <mass>0.595447</mass>
        <inertia>
          <ixx>0.000444025</ixx>
          <ixy>-4.7574e-08</ixy>
          <ixz>1.27031e-07</ixz>
          <iyy>0.000369582</iyy>
          <iyz>5.65243e-06</iyz>
          <izz>0.000271238</izz>
        </inertia>
      </inertial>
      <collision name='NeckYaw_collision'>
        <pose frame=''>0 0 0 0 -0 0</pose>
        <geometry>
          <mesh>
            <scale>0.001 0.001 0.001</scale>
            <uri>model://walkman_urdf/meshes/simple/NeckYaw.STL</uri>
          </mesh>
        </geometry>
        <surface>
          <contact>
            <ode/>
          </contact>
          <friction>
            <ode/>
          </friction>
        </surface>
      </collision>
      <visual name='NeckYaw_visual'>
        <pose frame=''>0 0 0 0 -0 0</pose>
        <geometry>
          <mesh>
            <scale>0.001 0.001 0.001</scale>
            <uri>model://walkman_urdf/meshes/NeckYaw.STL</uri>
          </mesh>
        </geometry>
        <material>
          <script>
            <name>Gazebo/Grey</name>
            <uri>file://media/materials/scripts/gazebo.material</uri>
          </script>
        </material>
      </visual>
      <gravity>1</gravity>
      <velocity_decay/>
    </link>
    <joint name='NeckYawj' type='revolute'>
      <child>NeckYaw</child>
      <parent>DWYTorso</parent>
      <axis>
        <xyz>0 0 1</xyz>
        <limit>
          <lower>-0.610865</lower>
          <upper>0.610865</upper>
          <effort>120</effort>
          <velocity>6.283</velocity>
        </limit>
        <dynamics>
          <damping>3</damping>
          <friction>0</friction>
          <spring_reference>0</spring_reference>
          <spring_stiffness>0</spring_stiffness>
        </dynamics>
        <use_parent_model_frame>1</use_parent_model_frame>
      </axis>
    </joint>
    <link name='NeckPitch'>
      <pose frame=''>0.0844 0.03425 0.487442 0 -0 0</pose>
      <inertial>
        <pose frame=''>0.006572 -0.03457 0.114028 0 -0 0</pose>
        <mass>3.13885</mass>
        <inertia>
          <ixx>0.0220672</ixx>
          <ixy>-3.25109e-05</ixy>
          <ixz>-0.0012059</ixz>
          <iyy>0.0191403</iyy>
          <iyz>-9.66721e-05</iyz>
          <izz>0.0213347</izz>
        </inertia>
      </inertial>
      <collision name='NeckPitch_collision'>
        <pose frame=''>0 0 0 0 -0 0</pose>
        <geometry>
          <mesh>
            <scale>0.001 0.001 0.001</scale>
            <uri>model://walkman_urdf/meshes/simple/NeckPitch.STL</uri>
          </mesh>
        </geometry>
        <surface>
          <contact>
            <ode/>
          </contact>
          <friction>
            <ode/>
          </friction>
        </surface>
      </collision>
      <visual name='NeckPitch_visual'>
        <pose frame=''>0 0 0 0 -0 0</pose>
        <geometry>
          <mesh>
            <scale>0.001 0.001 0.001</scale>
            <uri>model://walkman_urdf/meshes/NeckPitch.STL</uri>
          </mesh>
        </geometry>
        <material>
          <script>
            <name>Gazebo/Grey</name>
            <uri>file://media/materials/scripts/gazebo.material</uri>
          </script>
        </material>
      </visual>
      <gravity>1</gravity>
      <velocity_decay/>
    </link>
    <joint name='NeckPitchj' type='revolute'>
      <child>NeckPitch</child>
      <parent>NeckYaw</parent>
      <axis>
        <xyz>0 1 0</xyz>
        <limit>
          <lower>-0.261799</lower>
          <upper>1.0472</upper>
          <effort>120</effort>
          <velocity>6.283</velocity>
        </limit>
        <dynamics>
          <damping>3</damping>
          <friction>0</friction>
          <spring_reference>0</spring_reference>
          <spring_stiffness>0</spring_stiffness>
        </dynamics>
        <use_parent_model_frame>1</use_parent_model_frame>
      </axis>
    </joint>
    <link name='RShp'>
      <pose frame=''>0.114148 -0.169137 0.377276 -0.174533 -0 0.523599</pose>
      <inertial>
        <pose frame=''>-0.007446 -0.034108 0.00011 0 -0 0</pose>
        <mass>1.96287</mass>
        <inertia>
          <ixx>0.00535477</ixx>
          <ixy>-0.000364289</ixy>
          <ixz>1.50896e-05</ixz>
          <iyy>0.00339233</iyy>
          <iyz>-5.56923e-05</iyz>
          <izz>0.00689214</izz>
        </inertia>
      </inertial>
      <collision name='RShp_collision'>
        <pose frame=''>0 0 0 0 -0 0</pose>
        <geometry>
          <mesh>
            <scale>0.001 0.001 0.001</scale>
            <uri>model://walkman_urdf/meshes/simple/ShoulderPitch.STL</uri>
          </mesh>
        </geometry>
      </collision>
      <visual name='RShp_visual'>
        <pose frame=''>0 0 0 0 -0 0</pose>
        <geometry>
          <mesh>
            <scale>0.001 0.001 0.001</scale>
            <uri>model://walkman_urdf/meshes/ShoulderPitch.STL</uri>
          </mesh>
        </geometry>
      </visual>
    </link>
    <joint name='RShSag' type='revolute'>
      <child>RShp</child>
      <parent>DWYTorso</parent>
      <axis>
        <xyz>-0.492404 0.852869 -0.173648</xyz>
        <limit>
          <lower>-3.40339</lower>
          <upper>1.65806</upper>
          <effort>147</effort>
          <velocity>6.283</velocity>
        </limit>
        <dynamics>
          <damping>3</damping>
          <friction>0</friction>
          <spring_reference>0</spring_reference>
          <spring_stiffness>0</spring_stiffness>
        </dynamics>
        <use_parent_model_frame>1</use_parent_model_frame>
      </axis>
    </joint>
    <link name='RShr'>
      <pose frame=''>0.066604 -0.26709 0.388042 -0 0 0.523599</pose>
      <inertial>
        <pose frame=''>0.058142 -5.7e-05 -0.077478 0 -0 0</pose>
        <mass>1.85958</mass>
        <inertia>
          <ixx>0.0137766</ixx>
          <ixy>-3.77887e-05</ixy>
          <ixz>0.00376902</ixz>
          <iyy>0.0156775</iyy>
          <iyz>9.48935e-06</iyz>
          <izz>0.00463177</izz>
        </inertia>
      </inertial>
      <collision name='RShr_collision'>
        <pose frame=''>0 0 0 0 -0 0</pose>
        <geometry>
          <mesh>
            <scale>0.001 0.001 0.001</scale>
            <uri>model://walkman_urdf/meshes/simple/ShoulderRoll.STL</uri>
          </mesh>
        </geometry>
      </collision>
      <visual name='RShr_visual'>
        <pose frame=''>0 0 0 0 -0 0</pose>
        <geometry>
          <mesh>
            <scale>0.001 0.001 0.001</scale>
            <uri>model://walkman_urdf/meshes/ShoulderRoll.STL</uri>
          </mesh>
        </geometry>
      </visual>
    </link>
    <joint name='RShLat' type='revolute'>
      <child>RShr</child>
      <parent>RShp</parent>
      <axis>
        <xyz>0.866025 0.5 -0</xyz>
        <limit>
          <lower>-3.49066</lower>
          <upper>0</upper>
          <effort>120</effort>
          <velocity>6.283</velocity>
        </limit>
        <dynamics>
          <damping>3</damping>
          <friction>0</friction>
          <spring_reference>0</spring_reference>
          <spring_stiffness>0</spring_stiffness>
        </dynamics>
        <use_parent_model_frame>1</use_parent_model_frame>
      </axis>
    </joint>
    <link name='RShy'>
      <pose frame=''>0.144677 -0.222015 0.169892 -0 0 0.523599</pose>
      <inertial>
        <pose frame=''>0.014625 -0.000817 -0.028334 0 -0 0</pose>
        <mass>1.66781</mass>
        <inertia>
          <ixx>0.00644804</ixx>
          <ixy>0.000156391</ixy>
          <ixz>0.00122054</ixz>
          <iyy>0.00733721</iyy>
          <iyz>-8.99415e-05</iyz>
          <izz>0.00367384</izz>
        </inertia>
      </inertial>
      <collision name='RShy_collision'>
        <pose frame=''>0 0 0 0 -0 0</pose>
        <geometry>
          <mesh>
            <scale>0.001 0.001 0.001</scale>
            <uri>model://walkman_urdf/meshes/simple/ShoulderYaw.STL</uri>
          </mesh>
        </geometry>
      </collision>
      <visual name='RShy_visual'>
        <pose frame=''>0 0 0 0 -0 0</pose>
        <geometry>
          <mesh>
            <scale>0.001 0.001 0.001</scale>
            <uri>model://walkman_urdf/meshes/ShoulderYaw.STL</uri>
          </mesh>
        </geometry>
      </visual>
    </link>
    <joint name='RShYaw' type='revolute'>
      <child>RShy</child>
      <parent>RShr</parent>
      <axis>
        <xyz>-0 0 1</xyz>
        <limit>
          <lower>-2.61799</lower>
          <upper>2.61799</upper>
          <effort>147</effort>
          <velocity>6.283</velocity>
        </limit>
        <dynamics>
          <damping>3</damping>
          <friction>0</friction>
          <spring_reference>0</spring_reference>
          <spring_stiffness>0</spring_stiffness>
        </dynamics>
        <use_parent_model_frame>1</use_parent_model_frame>
      </axis>
    </joint>
    <link name='RElb'>
      <pose frame=''>0.211223 -0.247276 0.095892 -0 0 0.523599</pose>
      <inertial>
        <pose frame=''>-0.007683 0.040302 -0.043493 0 -0 0</pose>
        <mass>1.31573</mass>
        <inertia>
          <ixx>0.00433039</ixx>
          <ixy>0.000117374</ixy>
          <ixz>-0.000419232</ixz>
          <iyy>0.00385399</iyy>
          <iyz>0.00079573</iyz>
          <izz>0.00175947</izz>
        </inertia>
      </inertial>
      <collision name='RElb_collision'>
        <pose frame=''>0 0 0 0 -0 0</pose>
        <geometry>
          <mesh>
            <scale>0.001 0.001 0.001</scale>
            <uri>model://walkman_urdf/meshes/simple/Elbow.STL</uri>
          </mesh>
        </geometry>
      </collision>
      <visual name='RElb_visual'>
        <pose frame=''>0 0 0 0 -0 0</pose>
        <geometry>
          <mesh>
            <scale>0.001 0.001 0.001</scale>
            <uri>model://walkman_urdf/meshes/Elbow.STL</uri>
          </mesh>
        </geometry>
      </visual>
    </link>
    <joint name='RElbj' type='revolute'>
      <child>RElb</child>
      <parent>RShy</parent>
      <axis>
        <xyz>-0.5 0.866025 -0</xyz>
        <limit>
          <lower>-2.96706</lower>
          <upper>0.593412</upper>
          <effort>147</effort>
          <velocity>6.283</velocity>
        </limit>
        <dynamics>
          <damping>3</damping>
          <friction>0</friction>
          <spring_reference>0</spring_reference>
          <spring_stiffness>0</spring_stiffness>
        </dynamics>
        <use_parent_model_frame>1</use_parent_model_frame>
      </axis>
    </joint>
    <link name='RForearm'>
      <pose frame=''>0.170657 -0.207015 0.000892 -0 0 0.523599</pose>
      <inertial>
        <pose frame=''>-0.000111 -0.011591 -0.07816 0 -0 0</pose>
        <mass>1.49085</mass>
        <inertia>
          <ixx>0.00856921</ixx>
          <ixy>-1.78563e-05</ixy>
          <ixz>1.93794e-05</ixz>
          <iyy>0.00774542</iyy>
          <iyz>0.000328601</iyz>
          <izz>0.00274419</izz>
        </inertia>
      </inertial>
      <collision name='RForearm_collision'>
        <pose frame=''>0 0 0 0 -0 0</pose>
        <geometry>
          <mesh>
            <scale>0.001 0.001 0.001</scale>
            <uri>model://walkman_urdf/meshes/simple/Forearm.STL</uri>
          </mesh>
        </geometry>
      </collision>
      <visual name='RForearm_visual'>
        <pose frame=''>0 0 0 0 -0 0</pose>
        <geometry>
          <mesh>
            <scale>0.001 0.001 0.001</scale>
            <uri>model://walkman_urdf/meshes/Forearm.STL</uri>
          </mesh>
        </geometry>
      </visual>
    </link>
    <joint name='RForearmPlate' type='revolute'>
      <child>RForearm</child>
      <parent>RElb</parent>
      <axis>
        <xyz>-0 0 1</xyz>
        <limit>
          <lower>-2.61799</lower>
          <upper>2.61799</upper>
          <effort>55</effort>
          <velocity>6.283</velocity>
        </limit>
        <dynamics>
          <damping>0.03</damping>
          <friction>0</friction>
          <spring_reference>0</spring_reference>
          <spring_stiffness>0</spring_stiffness>
        </dynamics>
        <use_parent_model_frame>1</use_parent_model_frame>
      </axis>
    </joint>
    <link name='RWrMot2'>
      <pose frame=''>0.195157 -0.24945 -0.155108 -0 0 0.523599</pose>
      <inertial>
        <pose frame=''>-5e-06 0.038014 -0.069927 0 -0 0</pose>
        <mass>1.12636</mass>
        <inertia>
          <ixx>0.00518718</ixx>
          <ixy>-2.72444e-05</ixy>
          <ixz>2.28335e-06</ixz>
          <iyy>0.00480378</iyy>
          <iyz>0.000721657</iyz>
          <izz>0.00127714</izz>
        </inertia>
      </inertial>
      <collision name='RWrMot2_collision'>
        <pose frame=''>0 0 0 0 -0 0</pose>
        <geometry>
          <mesh>
            <scale>0.001 0.001 0.001</scale>
            <uri>model://walkman_urdf/meshes/simple/ForearmPitch.STL</uri>
          </mesh>
        </geometry>
      </collision>
      <visual name='RWrMot2_visual'>
        <pose frame=''>0 0 0 0 -0 0</pose>
        <geometry>
          <mesh>
            <scale>0.001 0.001 0.001</scale>
            <uri>model://walkman_urdf/meshes/ForearmPitch.STL</uri>
          </mesh>
        </geometry>
      </visual>
    </link>
    <joint name='RWrj1' type='revolute'>
      <child>RWrMot2</child>
      <parent>RForearm</parent>
      <axis>
        <xyz>-0.5 0.866025 -0</xyz>
        <limit>
          <lower>-1.5708</lower>
          <upper>1.5708</upper>
          <effort>55</effort>
          <velocity>6.283</velocity>
        </limit>
        <dynamics>
          <damping>0.03</damping>
          <friction>0</friction>
          <spring_reference>0</spring_reference>
          <spring_stiffness>0</spring_stiffness>
        </dynamics>
        <use_parent_model_frame>1</use_parent_model_frame>
      </axis>
    </joint>
    <link name='RWrMot3'>
      <pose frame=''>0.170657 -0.207015 -0.329108 -0 0 0.523599</pose>
      <inertial>
        <pose frame=''>0 0 0.031271 0 -0 0</pose>
        <mass>0.279664</mass>
        <inertia>
          <ixx>0.000144152</ixx>
          <ixy>9.86518e-08</ixy>
          <ixz>0</ixz>
          <iyy>0.00014417</iyy>
          <iyz>0</iyz>
          <izz>6.05006e-05</izz>
        </inertia>
      </inertial>
      <collision name='RWrMot3_collision'>
        <pose frame=''>0 0 0 0 -0 0</pose>
        <geometry>
          <box>
            <size>0.1 0.1 0.01</size>
          </box>
        </geometry>
      </collision>
      <visual name='RWrMot3_visual'>
        <pose frame=''>0 0 0 0 -0 0</pose>
        <geometry>
          <box>
            <size>0.1 0.1 0.01</size>
          </box>
        </geometry>
      </visual>
    </link>
    <joint name='RWrj2' type='revolute'>
      <child>RWrMot3</child>
      <parent>RWrMot2</parent>
      <axis>
        <xyz>-0 0 1</xyz>
        <limit>
          <lower>-2.61799</lower>
          <upper>2.61799</upper>
          <effort>27</effort>
          <velocity>6.283</velocity>
        </limit>
        <dynamics>
          <damping>0.03</damping>
          <friction>0</friction>
          <spring_reference>0</spring_reference>
          <spring_stiffness>0</spring_stiffness>
        </dynamics>
        <use_parent_model_frame>1</use_parent_model_frame>
      </axis>
    </joint>
    <static>0</static>
    <plugin name='xbot_plugin_handler' filename='libGazeboXBotPlugin.so'/>
    <pose frame=''>0 0 1.25 0 -0 0</pose>
  </model>
</sdf>
